ERROR:mylogger:RuntimeError hit
Traceback (most recent call last):
  File "Day-020/01-logging.py", line 25, in <module>
    raise RuntimeError
RuntimeError
